Workbook

Sheet bakimrecete
A1: recete_id | B1: line_id | C1: kod | D1: parca_tanimi | E1: adet | F1: birim | G1: fiyat_usd | H1: toplam_usd
A2: 30DN-9V_100 | B2: 1 | C2: XKBH-07137 | D2: Motor yağ filtresi | E2: 1 | F2: Ad | G2: =VLOOKUP(C:C,yedekparca!A:D,3,0) -> 8.077959 | H2: =E2*G2 -> 8.077959
A3: 30DN-9V_100 | B3: 2 | C3: Total Rubia Optima 1100 15W40 CK-4 | D3: Motor yağı | E3: 8.2 | F3: Litre | G3: =VLOOKUP(C:C,yedekparca!A:D,3,0) -> 4.7906977 | H3: =E3*G3 -> 39.283721
A4: 30DN-9V_100 | B4: 3 | C4: HF50-A0040 | D4: Şanzıman Filtresi | E4: 1 | F4: Ad | G4: =VLOOKUP(C:C,yedekparca!A:D,3,0) -> 11.136429 | H4: =E4*G4 -> 11.136429
A5: 30DN-9V_100 | B5: 4 | C5: Total AT 42 | D5: Şanzıman yağı | E5: 7 | F5: Litre | G5: =VLOOKUP(C:C,yedekparca!A:D,3,0) -> 7.1302326 | H5: =E5*G5 -> 49.911628
A6: 30DN-9V_100 | B6: 5 | C6: Total Dyn MPV | D6: Diferansiyel yağı | E6: 8.2 | F6: Litre | G6: =VLOOKUP(C:C,yedekparca!A:D,3,0) -> 3.6976744 | H6: =E6*G6 -> 30.32093
A7: 30DN-9V_100 | B7: 6 | C7: HYDBAKD01 | D7: Periyodik Bkm İşçilik Dizel1 | E7: 1 | F7: Ad | G7: =VLOOKUP(C:C,yedekparca!A:D,3,0) -> 58.139535 | H7: =E7*G7 -> 58.139535
A8: =SUBTOTAL(9,A2:A7) -> 0 | G8: Toplam 30DN9V_100 | H8: =SUBTOTAL(9,H2:H7) -> 196.8702
A9: 30DN-9V_250 | B9: 1 | C9: XKBH-07137 | D9: Motor yağ filtresi | E9: 1 | F9: Ad | G9: =VLOOKUP(C:C,yedekparca!A:D,3,0) -> 8.077959 | H9: =E9*G9 -> 8.077959
A10: 30DN-9V_250 | B10: 2 | C10: Total Rubia Optima 1100 15W40 CK-4 | D10: Motor yağı | E10: 8.2 | F10: Litre | G10: =VLOOKUP(C:C,yedekparca!A:D,3,0) -> 4.7906977 | H10: =E10*G10 -> 39.283721
A11: 30DN-9V_250 | B11: 3 | C11: HF50-A0040 | D11: Şanzıman Filtresi | E11: 1 | F11: Ad | G11: =VLOOKUP(C:C,yedekparca!A:D,3,0) -> 11.136429 | H11: =E11*G11 -> 11.136429
A12: 30DN-9V_250 | B12: 4 | C12: Total AT 42 | D12: Şanzıman yağı | E12: 7 | F12: Litre | G12: =VLOOKUP(C:C,yedekparca!A:D,3,0) -> 7.1302326 | H12: =E12*G12 -> 49.911628
A13: 30DN-9V_250 | B13: 5 | C13: Total Dyn MPV | D13: Diferansiyel yağı | E13: 8.2 | F13: Litre | G13: =VLOOKUP(C:C,yedekparca!A:D,3,0) -> 3.6976744 | H13: =E13*G13 -> 30.32093
A14: 30DN-9V_250 | B14: 6 | C14: HYDBAKD01 | D14: Periyodik Bkm İşçilik Dizel1 | E14: 1 | F14: Ad | G14: =VLOOKUP(C:C,yedekparca!A:D,3,0) -> 58.139535 | H14: =E14*G14 -> 58.139535
A15: =SUBTOTAL(9,A9:A14) -> 0 | G15: Toplam 30ND9V_250 | H15: =SUBTOTAL(9,H9:H14) -> 196.8702
A16: 30DN-9V_500 | B16: 1 | C16: XKBH-07137 | D16: Motor yağ filtresi | E16: 1 | F16: Ad | G16: =VLOOKUP(C:C,yedekparca!A:D,3,0) -> 8.077959 | H16: =E16*G16 -> 8.077959
A17: 30DN-9V_500 | B17: 2 | C17: Total Rubia Optima 1100 15W40 CK-4 | D17: Motor yağı | E17: 8.2 | F17: Litre | G17: =VLOOKUP(C:C,yedekparca!A:D,3,0) -> 4.7906977 | H17: =E17*G17 -> 39.283721
A18: 30DN-9V_500 | B18: 3 | C18: 31EE-02110-A | D18: Hidrolik hav. Filtresi | E18: 1 | F18: Ad | G18: =VLOOKUP(C:C,yedekparca!A:D,3,0) -> 3.382308 | H18: =E18*G18 -> 3.382308
A19: 30DN-9V_500 | B19: 4 | C19: 11FK-20090 | D19: Hava Filtresi iç | E19: 1 | F19: Ad | G19: =VLOOKUP(C:C,yedekparca!A:D,3,0) -> 21.283353 | H19: =E19*G19 -> 21.283353
A20: 30DN-9V_500 | B20: 5 | C20: 11FK-20080 | D20: Hava Filtresi dış | E20: 1 | F20: Ad | G20: =VLOOKUP(C:C,yedekparca!A:D,3,0) -> 29.343321 | H20: =E20*G20 -> 29.343321
A21: 30DN-9V_500 | B21: 6 | C21: XKBH-03363 | D21: Yakıt filtresi | E21: 1 | F21: Ad | G21: =VLOOKUP(C:C,yedekparca!A:D,3,0) -> 32.113935 | H21: =E21*G21 -> 32.113935
A22: 30DN-9V_500 | B22: 7 | C22: HYDBAKD02 | D22: Periyodik Bkm İşçilik Dizel2 | E22: 1 | F22: Ad | G22: =VLOOKUP(C:C,yedekparca!A:D,3,0) -> 93.023256 | H22: =E22*G22 -> 93.023256
A23: =SUBTOTAL(9,A16:A22) -> 0 | G23: Toplam 30ND9V_500 | H23: =SUBTOTAL(9,H16:H22) -> 226.50785
A24: 30DN-9V_1000 | B24: 1 | C24: XKBH-07137 | D24: Motor yağ filtresi | E24: 1 | F24: Ad | G24: =VLOOKUP(C:C,yedekparca!A:D,3,0) -> 8.077959 | H24: =E24*G24 -> 8.077959
A25: 30DN-9V_1000 | B25: 2 | C25: Total Rubia Optima 1100 15W40 CK-4 | D25: Motor yağı | E25: 8.2 | F25: Litre | G25: =VLOOKUP(C:C,yedekparca!A:D,3,0) -> 4.7906977 | H25: =E25*G25 -> 39.283721
A26: 30DN-9V_1000 | B26: 3 | C26: XKBH-03363 | D26: Yakıt filtresi | E26: 1 | F26: Ad | G26: =VLOOKUP(C:C,yedekparca!A:D,3,0) -> 32.113935 | H26: =E26*G26 -> 32.113935
A27: 30DN-9V_1000 | B27: 4 | C27: 11FK-20090 | D27: Hava Filtresi iç | E27: 1 | F27: Ad | G27: =VLOOKUP(C:C,yedekparca!A:D,3,0) -> 21.283353 | H27: =E27*G27 -> 21.283353
A28: 30DN-9V_1000 | B28: 5 | C28: 11FK-20080 | D28: Hava Filtresi dış | E28: 1 | F28: Ad | G28: =VLOOKUP(C:C,yedekparca!A:D,3,0) -> 29.343321 | H28: =E28*G28 -> 29.343321
A29: 30DN-9V_1000 | B29: 6 | C29: HF50-A0040 | D29: Şanzıman Filtresi | E29: 1 | F29: Ad | G29: =VLOOKUP(C:C,yedekparca!A:D,3,0) -> 11.136429 | H29: =E29*G29 -> 11.136429
A30: 30DN-9V_1000 | B30: 7 | C30: Total AT 42 | D30: Şanzıman yağı | E30: 7 | F30: Litre | G30: =VLOOKUP(C:C,yedekparca!A:D,3,0) -> 7.1302326 | H30: =E30*G30 -> 49.911628
A31: 30DN-9V_1000 | B31: 8 | C31: Total Dyn MPV | D31: Diferansiyel yağı | E31: 8.2 | F31: Litre | G31: =VLOOKUP(C:C,yedekparca!A:D,3,0) -> 3.6976744 | H31: =E31*G31 -> 30.32093
A32: 30DN-9V_1000 | B32: 9 | C32: TOTAL AZOLLA ZS 32 | D32: Fren yağı | E32: 0.5 | F32: Ad | G32: =VLOOKUP(C:C,yedekparca!A:D,3,0) -> 2.8069767 | H32: =E32*G32 -> 1.4034884
A33: 30DN-9V_1000 | B33: 10 | C33: 37HN-30070 | D33: Hidrolik dönüş filtresi | E33: 1 | F33: Ad | G33: =VLOOKUP(C:C,yedekparca!A:D,3,0) -> 45.805086 | H33: =E33*G33 -> 45.805086
A34: 30DN-9V_1000 | B34: 11 | C34: J05071404 | D34: Hidrolik Emiş filtresi | E34: 1 | F34: Ad | G34: =VLOOKUP(C:C,yedekparca!A:D,3,0) -> 22.524732 | H34: =E34*G34 -> 22.524732
A35: 30DN-9V_1000 | B35: 12 | C35: 31EE-02110-A | D35: Hid. havalandırma filtresi | E35: 1 | F35: Ad | G35: =VLOOKUP(C:C,yedekparca!A:D,3,0) -> 3.382308 | H35: =E35*G35 -> 3.382308
... A37: 30DN-9V_1000 | B37: 14 | C37: HYDBAKD03 | D37: Periyodik Bkm İşçilik Dizel3 | E37: 1 | F37: Ad | G37: =VLOOKUP(C:C,yedekparca!A:D,3,0) -> 139.53488 | H37: =E37*G37 -> 139.53488
A38: =SUBTOTAL(9,A24:A37) -> 0 | G38: Toplam 30DN9V_1000 | H38: =SUBTOTAL(9,H24:H37) -> 474.87139
A39: 30DN-9V_2000 | B39: 1 | C39: XKBH-07137 | D39: Motor yağ filtresi | E39: 1 | F39: Ad | G39: =VLOOKUP(C:C,yedekparca!A:D,3,0) -> 8.077959 | H39: =E39*G39 -> 8.077959
A40: 30DN-9V_2000 | B40: 2 | C40: Total Rubia Optima 1100 15W40 CK-4 | D40: Motor yağı | E40: 8.2 | F40: Litre | G40: =VLOOKUP(C:C,yedekparca!A:D,3,0) -> 4.7906977 | H40: =E40*G40 -> 39.283721
A41: 30DN-9V_2000 | B41: 3 | C41: XKBH-03363 | D41: Yakıt filtresi | E41: 1 | F41: Ad | G41: =VLOOKUP(C:C,yedekparca!A:D,3,0) -> 32.113935 | H41: =E41*G41 -> 32.113935
...

Sheet bakimpaket
A1: Makinamodel | B1: toplamsaat | C1: receteid | E1: Adet | H1: recete_id | I1: Toplam_usd | J1: model
A2: 30DN-9V | B2: 2000 | C2: 30DN9V_100 | D2: =bakimrecete!H8 -> 196.8702 | E2: 1 | H2: 30DN-9V_2000 | I2: =D2*E2+D3*E3+D4*E4+D5*E5+D6*E6 -> 2489.3737 | J2: 30DN-9V
C3: 30D9V_250 | D3: =bakimrecete!H15 -> 196.8702 | E3: 4 | H3: 30DN-9V_3000 | I3: =D31*E31+D32*E32+D33*E33+D34*E34+D35*E35 -> 3584.4933 | J3: 30DN-9V
C4: 30D9V_500 | D4: =bakimrecete!H23 -> 226.50785 | E4: 2 | H4: 30DN-9V_6000 | I4: =D60*E60+D61*E61+D62*E62+D63*E63+D64*E64 -> 7074.3806 | J4: 30DN-9V
C5: 30D9V_1000 | D5: =bakimrecete!H38 -> 474.87139 | E5: 1 | H5: 30DN-9V_9000 | I5: =D89*E89+D90*E90+D91*E91+D92*E92+D93*E93 -> 10462.004 | J5: 30DN-9V
C6: 30D9V_2000 | D6: =bakimrecete!H54 -> 577.13558 | E6: 1 | H6: 30DE-9V_2000 | I6: =D7*E7+D8*E8+D9*E9+D10*E10 -> 2174.0431 | J6: 30DE-9V
A7: 30DE-9V | B7: 2000 | C7: 30DE9V_100 | D7: =bakimrecete!H61 -> 224.73826 | E7: 1 | H7: 30DE-9V_3000 | I7: =D36*E36+D37*E37+D38*E38+D39*E39+D40*E40 -> 3996.2713 | J7: 30DE-9V
C8: 30DE9V_250 | D8: =bakimrecete!H68 -> 224.73826 | E8: 4 | H8: 30DE-9V_6000 | I8: =D65*E65+D66*E66+D67*E67+D68*E68+D69*E69 -> 7870.0686 | J8: 30DE-9V
C9: 30DE9V_500 | D9: =bakimrecete!H76 -> 276.73872 | E9: 2 | H9: 30DE-9V_9000 | I9: =D94*E94+D95*E95+D96*E96+D97*E97+D98*E98 -> 11641.602 | J9: 30DE-9V
C10: 30DE9V_1000 | D10: =bakimrecete!H90 -> 496.87438 | E10: 1 | H10: 50DN-9VB_2000 | I10: =D12*E12+D13*E13+D14*E14+D15*E15+D16*E16 -> 3643.4138 | J10: 50DN-9VB
C11: 30DE9V_2000 | D11: =bakimrecete!H105 -> 599.13857 | E11: 1 | H11: 50DN-9VB_3000 | I11: =D41*E41+D42*E42+D43*E43+D44*E44+D45*E45 -> 5217.7399 | J11: 50DN-9VB
A12: 50DN-9VB | B12: 2000 | C12: 50DN9VB_100 | D12: =bakimrecete!H112 -> 290.23299 | E12: 1 | H12: 50DN-9VB_6000 | I12: =D70*E70+D71*E71+D72*E72+D73*E73+D74*E74 -> 10349.775 | J12: 50DN-9VB
C13: 50DN9VB_250 | D13: =bakimrecete!H119 -> 290.23299 | E13: 4 | H13: 50DN-9VB_9000 | I13: =D99*E99+D100*E100+D101*E101+D102*E102+D103*E103 -> 15277.282 | J13: 50DN-9VB
C14: 50DN9VB_500 | D14: =bakimrecete!H129 -> 274.82547 | E14: 2 | H14: 70D-9V_2000 | I14: =D17*E17+D18*E18+D19*E19+D20*E20+D21*E21 -> 3463.3913 | J14: 70D-9V
C15: 50DN9VB_1000 | D15: =bakimrecete!H146 -> 719.03474 | E15: 1 | H15: 70D-9V_3000 | I15: =D46*E46+D47*E47+D48*E48+D49*E49+D50*E50 -> 4938.6788 | J15: 70D-9V
C16: 50DN9VB_2000 | D16: =bakimrecete!H164 -> 923.56311 | E16: 1 | H16: 70D-9V_6000 | I16: =D75*E75+D76*E76+D77*E77+D78*E78+D79*E79 -> 9875.6571 | J16: 70D-9V
A17: 70D-9V | B17: 2000 | C17: 70D9V_100 | D17: =bakimrecete!H171 -> 257.25842 | E17: 1 | H17: 70D-9V_9000 | I17: =D104*E104+D105*E105+D106*E106+D107*E107+D108*E108 -> 14451.675 | J17: 70D-9V
C18: 70D9V_250 | D18: =bakimrecete!H178 -> 257.25842 | E18: 4 | H18: 100D-9V_2000 | I18: =D22*E22+D23*E23+D24*E24+D25*E25+D26*E26 -> 4159.1222 | J18: 100D-9V
C19: 70D9V_500 | D19: =bakimrecete!H188 -> 274.82547 | E19: 2 | H19: 100D-9V_3000 | I19: =D51*E51+D52*E52+D53*E53+D54*E54+D55*E55 -> 5841.944 | J19: 100D-9V
C20: 70D9V_1000 | D20: =bakimrecete!H204 -> 580.54296 | E20: 1 | H20: 100D-9V_6000 | I20: =D80*E80+D81*E81+D82*E82+D83*E83+D84*E84 -> 11823.134 | J20: 100D-9V
C21: 70D9V_2000 | D21: =bakimrecete!H222 -> 1046.9053 | E21: 1 | H21: 100D-9V_9000 | I21: =D109*E109+D110*E110+D111*E111+D112*E112+D113*E113 -> 17337.962 | J21: 100D-9V
A22: 100D-9V | B22: 2000 | C22: 100D9V_100 | D22: =bakimrecete!H229 -> 327.1161 | E22: 1 | H22: 160D-9V_2000 | I22: =D27*E27+D28*E28+D29*E29+D30*E30 -> 5776.0592 | J22: 160D-9V
C23: 100D9V_250 | D23: =bakimrecete!H235 -> 176.88013 | E23: 4 | H23: 160D-9V_3000 | I23: =D56*E56+D57*E57+D58*E58+D59*E59 -> 6379.2572 | J23: 160D-9V
C24: 100D9V_500 | D24: =bakimrecete!H247 -> 470.44558 | E24: 2 | H24: 160D-9V_6000 | I24: =D85*E85+D86*E86+D87*E87+D88*E88 -> 11939.671 | J24: 160D-9V
C25: 100D9V_1000 | D25: =bakimrecete!H265 -> 858.61602 | E25: 1 | H25: 160D-9V_9000 | I25: =D114*E114+D115*E115+D116*E116+D117*E117 -> 19184.935 | J25: 160D-9V
C26: 100D9V_2000 | D26: =bakimrecete!H285 -> 1324.9784 | E26: 1 | H26: 15BTR-9_2000 | I26: =D118*E118+D119*E119+D120*E120 -> 416.61315 | J26: 15BTR-9
A27: 160D-9V | B27: 2000 | C27: 160D9V_100 | D27: =bakimrecete!H292 -> 320.74675 | E27: 1 | H27: 15BTR-9_3000 | I27: =D142*E142+D143*E143+D144*E144 -> 565.35476 | J27: 15BTR-9
C28: 160D9V_500 | D28: =bakimrecete!H301 -> 603.19798 | E28: 2 | H28: 15BTR-9_6000 | I28: =D166*E166+D167*E167+D168*E168 -> 1162.9351 | J28: 15BTR-9
C29: 160D9V_1000 | D29: =bakimrecete!H321 -> 1186.7533 | E29: 2 | H29: 15BTR-9_9000 | I29: =D193*E193+D194*E194+D195*E195 -> 1815.1942 | J29: 15BTR-9
C30: 160D9V_2000 | D30: =bakimrecete!H345 -> 1875.4099 | E30: 1 | H30: 20BT-9_2000 | I30: =D121*E121+D122*E122+D123*E123 -> 416.61315 | J30: 20BT-9
A31: 30DN-9V | B31: 3000 | C31: 30D9V_100 | D31: =bakimrecete!H8 -> 196.8702 | E31: 1 | H31: 20BT-9_3000 | I31: =D145*E145+D146*E146+D147*E147 -> 565.35476 | J31: 20BT-9
C32: 30D9V_250 | D32: =bakimrecete!H15 -> 196.8702 | E32: 6 | H32: 20BT-9_6000 | I32: =D169*E169+D170*E170+D171*E171 -> 1162.9351 | J32: 20BT-9
C33: 30D9V_500 | D33: =bakimrecete!H23 -> 226.50785 | E33: 3 | H33: 20BT-9_9000 | I33: =D193*E193+D194*E194+D195*E195 -> 1815.1942 | J33: 20BT-9
C34: 30D9V_1000 | D34: =bakimrecete!H38 -> 474.87139 | E34: 2 | H34: 18BT-9U_2000 | I34: =D124*E124+D125*E125+D126*E126 -> 420.83757 | J34: 18BT-9U
C35: 30D9V_2000 | D35: =bakimrecete!H54 -> 577.13558 | E35: 1 | H35: 18BT-9U_3000 | I35: =D148*E148+D149*E149+D150*E150 -> 569.57917 | J35: 18BT-9U
A36: 30DE-9V | B36: 3000 | C36: 30DE9V_100 | D36: =bakimrecete!H61 -> 224.73826 | E36: 1 | H36: 18BT-9U_6000 | I36: =D172*E172+D173*E173+D174*E174 -> 1175.6083 | J36: 18BT-9U
C37: 30DE9V_250 | D37: =bakimrecete!H68 -> 224.73826 | E37: 6 | H37: 18BT-9U_9000 | I37: =D196*E196+D197*E197+D198+E198 -> 1205.3156 | J37: 18BT-9U
C38: 30DE9V_500 | D38: =bakimrecete!H76 -> 276.73872 | E38: 3 | H38: 30B-9_2000 | I38: =D127*E127+D128*E128+D129*E129 -> 441.85074 | J38: 30B-9
C39: 30DE9V_1000 | D39: =bakimrecete!H90 -> 496.87438 | E39: 2 | H39: 30B-9_3000 | I39: =D151*E151+D152*E152+D153*E153 -> 593.14811 | J39: 30B-9
C40: 30DE9V_2000 | D40: =bakimrecete!H105 -> 599.13857 | E40: 1 | H40: 30B-9_6000 | I40: =D175*E175+D176*E176+D177*E177 -> 1239.7897 | J40: 30B-9
...

Sheet MakineListesi
A1: id | B1: model_code | C1: model_name | D1: type | E1: price_usd
A2: 1 | B2: 30DN-9V | C2: 30DN-9V Diesel Forklift | D2: Dizel | E2: 42300
A3: 2 | B3: 30DE-9V | C3: 30DE-9V Diesel Forklift | D3: Dizel | E3: 32500
A4: 3 | B4: 50DN-9VB | C4: 50DN-9VB Diesel Forklift | D4: Dizel | E4: 66920
A5: 4 | B5: 70D-9V | C5: 70D-9V Diesel Forklift | D5: Dizel | E5: 101100
A6: 5 | B6: 100D-9V | C6: 100D-9V Diesel Forklift | D6: Dizel | E6: 139500
A7: 6 | B7: 160D-9V | C7: 160D-9V Diesel Forklift | D7: Dizel | E7: 206500
A8: 7 | B8: 15BTR-9 | C8: 15BTR-9 Elektrikli Forklift | D8: Elektrikli | E8: 30500
A9: 8 | B9: 20BT-9 | C9: 20BT-9 Elektrikli Forklift | D9: Elektrikli | E9: 32500
A10: 9 | B10: 18BT-9U | C10: 18BT-9U Elektrikli Forklift | D10: Elektrikli | E10: 34500
A11: 10 | B11: 30B-9 | C11: 30B-9 Elektrikli Forklift | D11: Elektrikli | E11: 35000
A12: 11 | B12: 25BH-9 | C12: 25BH-9 Elektrikli Forklift | D12: Elektrikli | E12: 42500
A13: 12 | B13: 30BH-9 | C13: 30BH-9 Elektrikli Forklift | D13: Elektrikli | E13: 46300
... A16: 15 | B16: 30BE-X | C16: 30BE-X Elektrikli Forklift | D16: Elektrikli | E16: 41000

Sheet yedekparca
A1: kod | B1: parça_tanımı | C1: fiyat | D1: birim
A2: 3289492 | B2: Fan kayışı | C2: 198.81854 | D2: Ad
A3: 11EM-21041-A | B3: Hava filtresi dış | C3: 26.788599 | D3: Ad
A4: 11EM-21051-A | B4: Hava filtresi iç | C4: 14.356818 | D4: Ad
A5: 11FA-50900 | B5: Yakıt depo iç filtre | C5: 5.865066 | D5: Ad
A6: 11FK-20080 | B6: Hava Filtresi dış | C6: 29.343321 | D6: Ad
A7: 11FK-20090 | B7: Hava Filtresi iç | C7: 21.283353 | D7: Ad
A8: 11FQ-20110 | B8: Hava Filtresi iç | C8: 21.823083 | D8: Ad
A9: 11FQ-20150 | B9: Hava Filtresi iç | C9: 20.221884 | D9: Ad
A10: 11FQ-20210 | B10: Hava Filtresi dış | C10: 49.457259 | D10: Ad
A11: 11FQ-20250 | B11: Hava Filtresi dış | C11: 31.088448 | D11: Ad
A12: 11FQ-93740 | B12: Polen dış filtre(klima) | C12: 6.314841 | D12: Ad
A13: 11K9-21310 | B13: Hava Filtresi dış | C13: 93.229362 | D13: Ad
A14: 11K9-21320 | B14: Hava Filtresi iç | C14: 38.284848 | D14: Ad
... A105: HYDBAKE03 | B105: Periyodik Bkm. Hyundai Elektrikli 3 | C105: 104.65116 | D105: ad

Sheet tire
A1: model | B1: tire_price_usd | C1: tirepricesolid_usd
A2: 30DN-9V | B2: =N22*2+Q22*2 -> 520
A3: 30DE-9V | B3: =N25*2+Q25*2 -> 520
A4: 35DE-9V | B4: =N26*2+Q26*2 -> 520
A5: 50DN-9VB | B5: =N27*2+Q27*2 -> 550
A6: 70D-9V | B6: =N28*2+Q28*2 -> 600
A7: 100D-9V | B7: =N30*2+Q30*2 -> 2400
A8: 160D-9V | B8: =N31*2+Q31*2 -> 2600
A9: 15BTR-9 | B9: =N32*2+Q32*1 -> 220 | C9: =O32*2+R32*1 -> 258
A10: 20BT-9 | B10: =Q33*2+N33 -> 285 | C10: =O33*2+R33*2 -> 500
A11: 18BT-9U | B11: =N35*2+Q35*2 -> 410 | C11: =O35*2+R35*2 -> 500
A12: 30B-9 | B12: =N37*2+Q37*2 -> 560 | C12: =N37*2+R37*2 -> 620
A13: 30BH-9 | B13: =N39*2+Q39*2 -> 560 | C13: =O41*2+R41*2 -> 680
A14: 30B-9U | B14: =N41*2+Q41*2 -> 560 | C14: =O41*2+R41*2 -> 680
A15: 50B-9 | B15: =N42*2+Q42*2 -> 1240 | C15: =O42*2+R42*2 -> 1420
A16: 30BE-X | B16: =N44*2+Q44*2 -> 500 | C16: =O44*2+R44*2 -> 880
M19: önlastik | P19: arkalastik | S19: önçift
L20: Makinemodel | M20: önlastik kod | N20: Normalfiyat | O20: Solidfiyat | P20: arkalastik kod | Q20: Normalfiyat | R20: Solidfiyat | S20: önçift kod | T20: fiyat
L21: 25D-9V | M21: 7.00-12-12 PRx2 | N21: 125 | P21: 6.5-10-12 PRx2 | Q21: 110 | S21: 6.00-15-10 PRx4 | T21: 110
L22: 30D-9V | M22: 8.15-15-14 PRx2 | N22: 150 | P22: 6.5-10-12 PRx2 | Q22: 110 | S22: 6.00-15-10 PRx4 | T22: 11
L23: 35DN-9V | M23: 8.15-15-14 PRx2 | N23: 150 | P23: 6.5-10-12 PRx2 | Q23: 110 | S23: 6.00-15-10 PRx4 | T23: 110
L24: 25DE-9V | M24: 7.00-12-12 PRx2 | N24: 125 | P24: 6.5-10-12 PRx2 | Q24: 110 | S24: 6.00-15-10 PRx4 | T24: 110
L25: 30DE-9V | M25: 8.15-15-14 PRx2 | N25: 150 | P25: 6.5-10-12 PRx2 | Q25: 110 | S25: 6.00-15-10 PRx4 | T25: 110
L26: 35DE-9V | M26: 8.15-15-14 PRx2 | N26: 150 | P26: 6.5-10-12 PRx2 | Q26: 110 | S26: 6.00-15-10 PRx4 | T26: 110
L27: 50DN-9VB | M27: 8.25-15-14 PRx2 | N27: 150 | P27: 7.00-12-14 PRx2 | Q27: 125 | S27: 7.50-16-12 PRx4 | T27: 200
L28: 70D-9V | M28: 8.25-15-14 PRx2 | N28: 150 | P28: 8.25-15-14 PRx2 | Q28: 150 | S28: none
L29: 80D-9V | M29: 8.25-15-14 PRx2 | N29: 150 | P29: 8.25-15-14 PRx2 | Q29: 150 | S29: none
L30: 100D-9V | M30: 9.00-20-14 PRx2 | N30: 600 | P30: 9.00-20-14 PRx2 | Q30: 600 | S30: none
L31: 160D-9V | M31: 12.00-20-18 PRx2 | N31: 650 | P31: 12.00-20-18 PRx2 | Q31: 650 | S31: none
L32: 15BTR-9 | M32: 18×7-8x2 | N32: 70 | O32: 86 | P32: 18×7-8x1 | Q32: 80 | R32: 86
L33: 20BT-9 | M33: 200/50-10 | N33: 125 | O33: 150 | P33: 15×4.5-8x2 | Q33: 80 | R33: 100
L34: 15BT-9U | M34: 18×7-8x2 | N34: 80 | O34: 110 | P34: 15×4.5-8x2 | Q34: 80 | R34: 100
L35: 18BT-9U | M35: 200/50-10x2 | N35: 125 | O35: 150 | P35: 15×4.5-8x2 | Q35: 80 | R35: 100
L36: 20BT-9U | M36: 200/50-10x2 | N36: 125 | O36: 150 | P36: 15×4.5-8x2 | Q36: 80 | R36: 100
L37: 30B-9 | M37: 23×9-10 18PRx2 | N37: 200 | O37: 230 | P37: 18×7-8 16PRx2 | Q37: 80 | R37: 110
L38: 25BH-9 | M38: 23×9-10 (18PR)x2 | N38: 200 | O38: 230 | P38: 18×7-8 (16PR)x2 | Q38: 80 | R38: 110
L39: 30BH-9 | M39: 23×9-10 (18PR)x2 | N39: 200 | O39: 230 | P39: 18×7-8 (16PR)x2 | Q39: 80 | R39: 110
L40: 35BH-9 | M40: 23×10-12 (16PR)x2 | N40: 225 | O40: 260 | P40: 18×7-8 (16PR)x2 | Q40: 80 | R40: 110
L41: 30B-9U | M41: 23×9-10 18PRx2 | N41: 200 | O41: 230 | P41: 18×7-8 16PRx2 | Q41: 80 | R41: 110
L42: 50B-9 | M42: 28×12.5-15 24PRx2 | N42: 420 | O42: 480 | P42: 23×9-10 18PRx2 | Q42: 200 | R42: 230 | S42: 7.00-15 14PRx4
...

Sheet second_hand_values
A1: model | B1: annual_ working hour | C1: Lease period(year) | D1: 2Hand_value(good) | E1: 2Hand_value(avarage) | F1: 2Hand_value(worst)
A2: 30DN-9V | B2: 0-1500 | C2: 1 | D2: 76 | E2: 72 | F2: 65
A3: 30DE-9V | B3: 0-1500 | C3: 1 | D3: 76 | E3: 72 | F3: 65
A4: 50DN-9VB | B4: 0-1500 | C4: 1 | D4: 76 | E4: 72 | F4: 65
A5: 70D-9V | B5: 0-1500 | C5: 1 | D5: 76 | E5: 72 | F5: 65
A6: 100D-9V | B6: 0-1500 | C6: 1 | D6: 76 | E6: 72 | F6: 65
A7: 160D-9V | B7: 0-1500 | C7: 1 | D7: 76 | E7: 72 | F7: 65
A8: 30DN-9V | B8: 1500-2500 | C8: 1 | D8: 72 | E8: 68.4 | F8: 61.2
A9: 30DE-9V | B9: 1500-2500 | C9: 1 | D9: 72 | E9: 68.4 | F9: 61.2
A10: 50DN-9VB | B10: 1500-2500 | C10: 1 | D10: 72 | E10: 68.4 | F10: 61.2
A11: 70D-9V | B11: 1500-2500 | C11: 1 | D11: 72 | E11: 68.4 | F11: 61.2
A12: 100D-9V | B12: 1500-2500 | C12: 1 | D12: 72 | E12: 68.4 | F12: 61.2
A13: 160D-9V | B13: 1500-2500 | C13: 1 | D13: 72 | E13: 68.4 | F13: 61.2
... A169: 30BE-X | B169: 3500-4500 | C169: 3 | D169: 42 | E169: 39.9 | F169: 35.7
